<?xml version="1.0"?>
<!--
  Demo-only visual model.

  This file preserves the original link names, joint names, joint origins, and
  wheel geometry so it remains compatible with the original dry-run TF and
  joint_states. Only the base visual width is narrowed to avoid the simplified
  body mesh visually swallowing the wheel modules during RViz demos.
-->
<robot name="mars_rover_demo" xmlns:xacro="http://www.ros.org/wiki/xacro">
  <xacro:property name="wheelbase" value="0.706"/>
  <xacro:property name="track_width" value="0.288"/>
  <xacro:property name="base_length" value="0.82"/>
  <xacro:property name="base_width" value="0.22"/>
  <xacro:property name="base_height" value="0.10"/>
  <xacro:property name="steering_height" value="0.12"/>
  <xacro:property name="wheel_radius" value="0.09"/>
  <xacro:property name="wheel_width" value="0.045"/>

  <material name="base_gray">
    <color rgba="0.35 0.38 0.40 1.0"/>
  </material>
  <material name="steering_blue">
    <color rgba="0.05 0.25 0.75 1.0"/>
  </material>
  <material name="wheel_black">
    <color rgba="0.03 0.03 0.03 1.0"/>
  </material>

  <link name="base_link">
    <visual>
      <origin xyz="0 0 0.08" rpy="0 0 0"/>
      <geometry>
        <box size="${base_length} ${base_width} ${base_height}"/>
      </geometry>
      <material name="base_gray"/>
    </visual>
  </link>

  <xacro:macro name="wheel_module" params="prefix x y">
    <link name="${prefix}_steering_link">
      <visual>
        <origin xyz="0 0 -0.03" rpy="0 0 0"/>
        <geometry>
          <cylinder radius="0.045" length="${steering_height}"/>
        </geometry>
        <material name="steering_blue"/>
      </visual>
    </link>

    <joint name="${prefix}_steering_joint" type="continuous">
      <parent link="base_link"/>
      <child link="${prefix}_steering_link"/>
      <origin xyz="${x} ${y} 0.02" rpy="0 0 0"/>
      <axis xyz="0 0 1"/>
    </joint>

    <link name="${prefix}_wheel_link">
      <visual>
        <origin xyz="0 0 -0.10" rpy="1.5708 0 0"/>
        <geometry>
          <cylinder radius="${wheel_radius}" length="${wheel_width}"/>
        </geometry>
        <material name="wheel_black"/>
      </visual>
    </link>

    <joint name="${prefix}_drive_joint" type="continuous">
      <parent link="${prefix}_steering_link"/>
      <child link="${prefix}_wheel_link"/>
      <origin xyz="0 0 -0.08" rpy="0 0 0"/>
      <axis xyz="0 1 0"/>
    </joint>
  </xacro:macro>

  <xacro:wheel_module prefix="front_left" x="${wheelbase / 2.0}" y="${track_width / 2.0}"/>
  <xacro:wheel_module prefix="front_right" x="${wheelbase / 2.0}" y="${-track_width / 2.0}"/>
  <xacro:wheel_module prefix="rear_left" x="${-wheelbase / 2.0}" y="${track_width / 2.0}"/>
  <xacro:wheel_module prefix="rear_right" x="${-wheelbase / 2.0}" y="${-track_width / 2.0}"/>
</robot>
